[2024-09-01T19:31:18.301+0000] {taskinstance.py:1125} INFO - Dependencies all met for dep_context=non-requeueable deps ti=<TaskInstance: news_etl_pipeline.news_extraction scheduled__2024-08-31T00:00:00+00:00 [queued]>
[2024-09-01T19:31:18.311+0000] {taskinstance.py:1125} INFO - Dependencies all met for dep_context=requeueable deps ti=<TaskInstance: news_etl_pipeline.news_extraction scheduled__2024-08-31T00:00:00+00:00 [queued]>
[2024-09-01T19:31:18.312+0000] {taskinstance.py:1331} INFO - Starting attempt 2 of 2
[2024-09-01T19:31:18.326+0000] {taskinstance.py:1350} INFO - Executing <Task(PythonOperator): news_extraction> on 2024-08-31 00:00:00+00:00
[2024-09-01T19:31:18.331+0000] {standard_task_runner.py:57} INFO - Started process 240 to run task
[2024-09-01T19:31:18.334+0000] {standard_task_runner.py:84} INFO - Running: ['***', 'tasks', 'run', 'news_etl_pipeline', 'news_extraction', 'scheduled__2024-08-31T00:00:00+00:00', '--job-id', '5', '--raw', '--subdir', 'DAGS_FOLDER/news_dag.py', '--cfg-path', '/tmp/tmpj_nqbp_a']
[2024-09-01T19:31:18.336+0000] {standard_task_runner.py:85} INFO - Job 5: Subtask news_extraction
[2024-09-01T19:31:18.388+0000] {task_command.py:410} INFO - Running <TaskInstance: news_etl_pipeline.news_extraction scheduled__2024-08-31T00:00:00+00:00 [running]> on host a3ab3ee2c7f8
[2024-09-01T19:31:18.629+0000] {taskinstance.py:1570} INFO - Exporting env vars: AIRFLOW_CTX_DAG_OWNER='Bhargav Kumar Aathava' AIRFLOW_CTX_DAG_ID='news_etl_pipeline' AIRFLOW_CTX_TASK_ID='news_extraction' AIRFLOW_CTX_EXECUTION_DATE='2024-08-31T00:00:00+00:00' AIRFLOW_CTX_TRY_NUMBER='2' AIRFLOW_CTX_DAG_RUN_ID='scheduled__2024-08-31T00:00:00+00:00'
[2024-09-01T19:31:18.630+0000] {logging_mixin.py:149} INFO - connected to News Api!
[2024-09-01T19:31:18.847+0000] {logging_mixin.py:149} INFO - Extracted data from News Api!
[2024-09-01T19:31:18.852+0000] {taskinstance.py:1847} ERROR - Task failed with exception
Traceback (most recent call last):
  File "/home/airflow/.local/lib/python3.7/site-packages/airflow/operators/python.py", line 181, in execute
    return_value = self.execute_callable()
  File "/home/airflow/.local/lib/python3.7/site-packages/airflow/operators/python.py", line 198, in execute_callable
    return self.python_callable(*self.op_args, **self.op_kwargs)
  File "/opt/airflow/pipelines/news_pipeline.py", line 20, in news_pipeline
    load_data_to_csv(news_df, file_path)
  File "/opt/airflow/etls/news_etl.py", line 29, in load_data_to_csv
    news_df.to_csv(file_path, index=False)
  File "/home/airflow/.local/lib/python3.7/site-packages/pandas/core/generic.py", line 3482, in to_csv
    storage_options=storage_options,
  File "/home/airflow/.local/lib/python3.7/site-packages/pandas/io/formats/format.py", line 1105, in to_csv
    csv_formatter.save()
  File "/home/airflow/.local/lib/python3.7/site-packages/pandas/io/formats/csvs.py", line 243, in save
    storage_options=self.storage_options,
  File "/home/airflow/.local/lib/python3.7/site-packages/pandas/io/common.py", line 707, in get_handle
    newline="",
FileNotFoundError: [Errno 2] No such file or directory: './data/top_headlines_20240901.csv'
[2024-09-01T19:31:18.876+0000] {taskinstance.py:1373} INFO - Marking task as FAILED. dag_id=news_etl_pipeline, task_id=news_extraction, execution_date=20240831T000000, start_date=20240901T193118, end_date=20240901T193118
[2024-09-01T19:31:18.892+0000] {standard_task_runner.py:109} ERROR - Failed to execute job 5 for task news_extraction ([Errno 2] No such file or directory: './data/top_headlines_20240901.csv'; 240)
[2024-09-01T19:31:18.908+0000] {local_task_job_runner.py:232} INFO - Task exited with return code 1
[2024-09-01T19:31:18.936+0000] {taskinstance.py:2674} INFO - 0 downstream tasks scheduled from follow-on schedule check
