[2024-09-01T22:20:05.130+0000] {taskinstance.py:1125} INFO - Dependencies all met for dep_context=non-requeueable deps ti=<TaskInstance: news_etl_pipeline.uploading_to_aws_s3 manual__2024-09-01T22:20:02.141469+00:00 [queued]>
[2024-09-01T22:20:05.138+0000] {taskinstance.py:1125} INFO - Dependencies all met for dep_context=requeueable deps ti=<TaskInstance: news_etl_pipeline.uploading_to_aws_s3 manual__2024-09-01T22:20:02.141469+00:00 [queued]>
[2024-09-01T22:20:05.139+0000] {taskinstance.py:1331} INFO - Starting attempt 1 of 1
[2024-09-01T22:20:05.149+0000] {taskinstance.py:1350} INFO - Executing <Task(PythonOperator): uploading_to_aws_s3> on 2024-09-01 22:20:02.141469+00:00
[2024-09-01T22:20:05.154+0000] {standard_task_runner.py:57} INFO - Started process 481 to run task
[2024-09-01T22:20:05.156+0000] {standard_task_runner.py:84} INFO - Running: ['***', 'tasks', 'run', 'news_etl_pipeline', 'uploading_to_aws_s3', 'manual__2024-09-01T22:20:02.141469+00:00', '--job-id', '11', '--raw', '--subdir', 'DAGS_FOLDER/news_dag.py', '--cfg-path', '/tmp/tmp5c3sw9qs']
[2024-09-01T22:20:05.158+0000] {standard_task_runner.py:85} INFO - Job 11: Subtask uploading_to_aws_s3
[2024-09-01T22:20:05.198+0000] {task_command.py:410} INFO - Running <TaskInstance: news_etl_pipeline.uploading_to_aws_s3 manual__2024-09-01T22:20:02.141469+00:00 [running]> on host d87ef426a446
[2024-09-01T22:20:05.264+0000] {taskinstance.py:1570} INFO - Exporting env vars: AIRFLOW_CTX_DAG_OWNER='Bhargav Kumar Aathava' AIRFLOW_CTX_DAG_ID='news_etl_pipeline' AIRFLOW_CTX_TASK_ID='uploading_to_aws_s3' AIRFLOW_CTX_EXECUTION_DATE='2024-09-01T22:20:02.141469+00:00' AIRFLOW_CTX_TRY_NUMBER='1' AIRFLOW_CTX_DAG_RUN_ID='manual__2024-09-01T22:20:02.141469+00:00'
[2024-09-01T22:20:05.782+0000] {logging_mixin.py:149} INFO - Bucket already exists
[2024-09-01T22:20:05.859+0000] {taskinstance.py:1847} ERROR - Task failed with exception
Traceback (most recent call last):
  File "/home/airflow/.local/lib/python3.7/site-packages/s3fs/core.py", line 688, in _lsdir
    versions=versions,
  File "/home/airflow/.local/lib/python3.7/site-packages/s3fs/core.py", line 733, in _iterdir
    async for i in it:
  File "/home/airflow/.local/lib/python3.7/site-packages/aiobotocore/paginate.py", line 30, in __anext__
    response = await self._make_request(current_kwargs)
  File "/home/airflow/.local/lib/python3.7/site-packages/aiobotocore/client.py", line 358, in _make_api_call
    raise error_class(parsed_response, operation_name)
botocore.exceptions.ClientError: An error occurred (AccessDenied) when calling the ListObjectsV2 operation: Access Denied

The above exception was the direct cause of the following exception:

Traceback (most recent call last):
  File "/home/airflow/.local/lib/python3.7/site-packages/airflow/operators/python.py", line 181, in execute
    return_value = self.execute_callable()
  File "/home/airflow/.local/lib/python3.7/site-packages/airflow/operators/python.py", line 198, in execute_callable
    return self.python_callable(*self.op_args, **self.op_kwargs)
  File "/opt/airflow/pipelines/aws_s3_pipeline.py", line 10, in upload_s3_pipeline
    upload_to_s3(s3, file_path, AWS_BUCKET_NAME, file_path.split('/')[-1])
  File "/opt/airflow/etls/aws_etl.py", line 24, in upload_to_s3
    s3.put(file_path, bucket+'/raw/'+ s3_file_name)
  File "/home/airflow/.local/lib/python3.7/site-packages/fsspec/asyn.py", line 114, in wrapper
    return sync(self.loop, func, *args, **kwargs)
  File "/home/airflow/.local/lib/python3.7/site-packages/fsspec/asyn.py", line 99, in sync
    raise return_result
  File "/home/airflow/.local/lib/python3.7/site-packages/fsspec/asyn.py", line 54, in _runner
    result[0] = await coro
  File "/home/airflow/.local/lib/python3.7/site-packages/fsspec/asyn.py", line 487, in _put
    lpaths, rpath, exists=isinstance(rpath, str) and await self._isdir(rpath)
  File "/home/airflow/.local/lib/python3.7/site-packages/s3fs/core.py", line 1347, in _isdir
    return bool(await self._lsdir(path))
  File "/home/airflow/.local/lib/python3.7/site-packages/s3fs/core.py", line 696, in _lsdir
    raise translate_boto_error(e)
PermissionError: Access Denied
[2024-09-01T22:20:05.898+0000] {taskinstance.py:1373} INFO - Marking task as FAILED. dag_id=news_etl_pipeline, task_id=uploading_to_aws_s3, execution_date=20240901T222002, start_date=20240901T222005, end_date=20240901T222005
[2024-09-01T22:20:05.908+0000] {standard_task_runner.py:109} ERROR - Failed to execute job 11 for task uploading_to_aws_s3 (Access Denied; 481)
[2024-09-01T22:20:05.931+0000] {local_task_job_runner.py:232} INFO - Task exited with return code 1
[2024-09-01T22:20:05.945+0000] {taskinstance.py:2674} INFO - 0 downstream tasks scheduled from follow-on schedule check
